<mujoco model="scene">
  <compiler angle="radian" meshdir="assets/"/>

  <option timestep="0.005" impratio="10" integrator="implicitfast" cone="elliptic" iterations="10" ls_iterations="20"/>

  <visual>
    <global azimuth="160" elevation="-20"/>
    <headlight ambient="0.3 0.3 0.3" diffuse="0.6 0.6 0.6" specular="0 0 0"/>
    <scale forcewidth="0.02" contactwidth="0.1" contactheight="0.05" camera="0.2" framelength="0.75" framewidth="0.025"/>
    <rgba haze="0.15 0.25 0.35 1"/>
  </visual>

  <default>
    <default class="so101">
      <joint armature="0.005" damping="1" frictionloss="0.1"/>
      <general biastype="affine" gainprm="50" biasprm="0 -50"/>
      <default class="visual">
        <geom type="mesh" contype="0" conaffinity="0" group="2"/>
      </default>
      <default class="collision">
        <geom group="3"/>
      </default>
      <default class="collision_gripper">
        <geom condim="6" group="3" priority="1" friction="1 0.005 0.0005" solref="0.01" rgba="1 0 0 1"/>
      </default>
      <default class="collision_gripper_mesh">
        <geom condim="6" group="4" priority="1" friction="1 0.005 0.0005" solref="0.01" rgba="1 0 0 1"/>
      </default>
    </default>
    <default class="sts3215">
      <joint armature="0.028" damping="0.6" frictionloss="0.052"/>
      <geom contype="0" conaffinity="0"/>
      <general forcerange="-2.94 2.94" biastype="affine" gainprm="998.22" biasprm="0 -998.22 -2.731"/>
    </default>
    <default class="backlash">
      <joint limited="true" range="-0.0087267 0.0087267" armature="0.01" damping="0.01"/>
    </default>
    <default class="d435i">
      <material specular="0" shininess="0.25"/>
      <default class="d435i_visual">
        <geom type="mesh" contype="0" conaffinity="0" group="2"/>
      </default>
      <default class="d435i_collision">
        <geom type="mesh" group="3"/>
      </default>
    </default>
  </default>

  <asset>
    <texture type="skybox" colorspace="auto" builtin="gradient" rgb1="0.3 0.5 0.7" rgb2="0 0 0" width="512" height="3072"/>
    <texture type="2d" colorspace="auto" name="groundplane" builtin="checker" mark="edge" rgb1="0.2 0.3 0.4" rgb2="0.1 0.2 0.3" markrgb="0.8 0.8 0.8" width="300" height="300"/>
    <material name="arducam_material" reflectance="0.2" rgba="0.15 0.15 0.15 1"/>
    <material name="base_motor_holder_so101_v1_material" rgba="1 0.82 0.12 1"/>
    <material name="base_so101_v2_material" rgba="1 0.82 0.12 1"/>
    <material name="sts3215_03a_v1_material" rgba="0.1 0.1 0.1 1"/>
    <material name="waveshare_mounting_plate_so101_v2_material" rgba="1 0.82 0.12 1"/>
    <material name="motor_holder_so101_base_v1_material" rgba="1 0.82 0.12 1"/>
    <material name="rotation_pitch_so101_v1_material" rgba="1 0.82 0.12 1"/>
    <material name="upper_arm_so101_v1_material" rgba="1 0.82 0.12 1"/>
    <material name="under_arm_so101_v1_material" rgba="1 0.82 0.12 1"/>
    <material name="motor_holder_so101_wrist_v1_material" rgba="1 0.82 0.12 1"/>
    <material name="sts3215_03a_no_horn_v1_material" rgba="0.1 0.1 0.1 1"/>
    <material name="wrist_roll_pitch_so101_v2_material" rgba="1 0.82 0.12 1"/>
    <material name="wrist_roll_follower_so101_v1_material" rgba="1 0.82 0.12 1"/>
    <material name="moving_jaw_so101_v1_material" rgba="1 0.82 0.12 1"/>
    <material name="Black_Acrylic" class="d435i" rgba="0.07036 0.07036 0.07036 1"/>
    <material name="Cameras_Gray" class="d435i" rgba="0.296138 0.296138 0.296138 1"/>
    <material name="IR_Emitter_Lens" class="d435i" rgba="0.28744 0.665387 0.327778 1"/>
    <material name="IR_Lens" class="d435i" rgba="0.035601 0.035601 0.035601 1"/>
    <material name="IR_Rim" class="d435i" rgba="0.799102 0.806952 0.799103 1"/>
    <material name="Metal_Casing" class="d435i"/>
    <material name="RGB_Pupil" class="d435i" rgba="0.08714 0.002866 0.009346 1"/>
    <material name="groundplane" texture="groundplane" texuniform="true" texrepeat="5 5" reflectance="0.2"/>
    <mesh name="waveshare_mounting_plate_so101_v2" content_type="model/stl" file="waveshare_mounting_plate_so101_v2.stl"/>
    <mesh name="sts3215_03a_v1" content_type="model/stl" file="sts3215_03a_v1.stl"/>
    <mesh name="motor_holder_so101_base_v1" content_type="model/stl" file="motor_holder_so101_base_v1.stl"/>
    <mesh name="wrist_roll_follower_so101_v1" content_type="model/stl" file="wrist_roll_follower_so101_v1.stl"/>
    <mesh name="moving_jaw_so101_v1" content_type="model/stl" file="moving_jaw_so101_v1.stl"/>
    <mesh name="base_motor_holder_so101_v1" content_type="model/stl" file="base_motor_holder_so101_v1.stl"/>
    <mesh name="upper_arm_so101_v1" content_type="model/stl" file="upper_arm_so101_v1.stl"/>
    <mesh name="wrist_roll_pitch_so101_v2" content_type="model/stl" file="wrist_roll_pitch_so101_v2.stl"/>
    <mesh name="under_arm_so101_v1" content_type="model/stl" file="under_arm_so101_v1.stl"/>
    <mesh name="rotation_pitch_so101_v1" content_type="model/stl" file="rotation_pitch_so101_v1.stl"/>
    <mesh name="motor_holder_so101_wrist_v1" content_type="model/stl" file="motor_holder_so101_wrist_v1.stl"/>
    <mesh name="sts3215_03a_no_horn_v1" content_type="model/stl" file="sts3215_03a_no_horn_v1.stl"/>
    <mesh name="base_so101_v2" content_type="model/stl" file="base_so101_v2.stl"/>
    <mesh name="moving_jaw_so101_gripper_v1" content_type="model/stl" file="moving_jaw_so101_gripper_v1.stl"/>
    <mesh name="wrist_roll_follower_so101_camera_mount" content_type="model/stl" file="wrist_roll_follower_so101_camera_mount.stl"/>
    <mesh name="wrist_roll_follower_so101_gripper_part0_v1" content_type="model/stl" file="wrist_roll_follower_so101_gripper_part0_v1.stl"/>
    <mesh name="moving_jaw_so101_gripper_part0_v1" content_type="model/stl" file="moving_jaw_so101_gripper_part0_v1.stl"/>
    <mesh name="moving_jaw_so101_gripper_part1_v1" content_type="model/stl" file="moving_jaw_so101_gripper_part1_v1.stl"/>
    <mesh name="ArduCam_M12Lens" content_type="model/stl" file="ArduCam_M12Lens.stl" scale="0.001 0.001 0.001"/>
    <mesh name="d435i_0" content_type="model/obj" file="../realsense_d435i/assets/d435i_0.obj"/>
    <mesh name="d435i_1" content_type="model/obj" file="../realsense_d435i/assets/d435i_1.obj"/>
    <mesh name="d435i_2" content_type="model/obj" file="../realsense_d435i/assets/d435i_2.obj"/>
    <mesh name="d435i_3" content_type="model/obj" file="../realsense_d435i/assets/d435i_3.obj"/>
    <mesh name="d435i_4" content_type="model/obj" file="../realsense_d435i/assets/d435i_4.obj"/>
    <mesh name="d435i_5" content_type="model/obj" file="../realsense_d435i/assets/d435i_5.obj"/>
    <mesh name="d435i_6" content_type="model/obj" file="../realsense_d435i/assets/d435i_6.obj"/>
    <mesh name="d435i_7" content_type="model/obj" file="../realsense_d435i/assets/d435i_7.obj"/>
    <mesh name="d435i_8" content_type="model/obj" file="../realsense_d435i/assets/d435i_8.obj"/>
  </asset>

  <worldbody>
    <geom name="floor" size="0 0 0.05" type="plane" material="groundplane"/>
    <light pos="0 0 1.5" dir="0 0 -1" type="directional"/>
    <light pos="0 0 3.5" dir="0 0 -1" type="directional"/>
    <body name="base" childclass="so101">
      <inertial pos="0.0137179 -5.19711e-05 0.0334843" quat="0.420519 0.558762 0.57198 0.428704" mass="0.147" diaginertia="0.000136127 0.000131807 0.000113233"/>
      <geom class="visual" pos="-0.006365 -9.9e-05 -0.0024" quat="0.5 0.5 0.5 0.5" material="base_motor_holder_so101_v1_material" mesh="base_motor_holder_so101_v1"/>
      <geom class="visual" pos="-0.006365 0 -0.0024" quat="0.5 0.5 0.5 0.5" material="base_so101_v2_material" mesh="base_so101_v2"/>
      <geom class="visual" pos="0.0263353 0 0.0437" quat="1 0 0 0" material="sts3215_03a_v1_material" mesh="sts3215_03a_v1"/>
      <geom class="visual" pos="-0.0309827 -0.000199 0.0474" quat="0.5 0.5 0.5 0.5" material="waveshare_mounting_plate_so101_v2_material" mesh="waveshare_mounting_plate_so101_v2"/>
      <site name="baseframe" pos="0 0 0" group="3"/>
      <body name="shoulder" pos="0.0388353 0 0.0624" quat="0 0 -1 0">
        <inertial pos="-0.0307604 -1.7e-05 -0.0252713" quat="0.999865 0.00149563 0.0097084 0.0132043" mass="0.100006" diaginertia="8.37836e-05 8.10388e-05 2.39552e-05"/>
        <joint name="shoulder_pan" class="sts3215" pos="0 0 0" axis="0 0 1" range="-1.91986 1.91986"/>
        <geom class="visual" pos="-0.030399 0.000422 -0.0417" quat="0.5 0.5 0.5 -0.5" material="sts3215_03a_v1_material" mesh="sts3215_03a_v1"/>
        <geom class="collision" size="0.023 0.015 0.01" pos="-0.030399 0.000422 -0.0387" quat="0.5 0.5 0.5 -0.5" type="box"/>
        <geom class="visual" pos="-0.067599 -0.0001778 0.01585" quat="0.5 0.5 -0.5 0.5" material="motor_holder_so101_base_v1_material" mesh="motor_holder_so101_base_v1"/>
        <geom class="collision" size="0.038 0.025 0.02" pos="-0.025 0 0" quat="0.5 0.5 -0.5 0.5" type="box"/>
        <geom class="visual" pos="0.012201 2.2e-05 0.0464" quat="0.707107 -0.707107 0 0" material="rotation_pitch_so101_v1_material" mesh="rotation_pitch_so101_v1"/>
        <body name="upper_arm" pos="-0.0303992 -0.0182778 -0.0542" quat="0.5 -0.5 -0.5 -0.5">
          <inertial pos="-0.089847 -0.008382 0.018409" quat="0.453195 0.454063 0.541891 0.542951" mass="0.103" diaginertia="0.000150873 0.000142487 3.72451e-05"/>
          <joint name="shoulder_lift" class="sts3215" pos="0 0 0" axis="0 0 1" range="-1.74533 1.74533"/>
          <geom class="visual" pos="-0.11257 -0.0155 0.0187" quat="0 -0.707107 0.707107 0" material="sts3215_03a_v1_material" mesh="sts3215_03a_v1"/>
          <geom class="collision" size="0.01 0.07 0.03" pos="-0.06 0 0.02" quat="0 -0.707107 0.707107 0" type="box"/>
          <geom class="visual" pos="-0.065085 0.012 0.0182" quat="0 1 0 0" material="upper_arm_so101_v1_material" mesh="upper_arm_so101_v1"/>
          <geom class="collision" size="0.01 0.02 0.015" pos="-0.12 -0.014 0.0182" quat="0 1 0 0" type="box"/>
          <body name="lower_arm" pos="-0.11257 -0.028 0" quat="0.707107 0 0 0.707107">
            <inertial pos="-0.09807 0.0032438 0.018283" quat="0.510729 0.517006 0.487966 0.483477" mass="0.104" diaginertia="0.000160262 0.000145304 2.83125e-05"/>
            <joint name="elbow_flex" class="sts3215" pos="0 0 0" axis="0 0 1" range="-1.69 1.69"/>
            <geom class="visual" pos="-0.06485 -0.032 0.0182" quat="0 1 0 0" material="under_arm_so101_v1_material" mesh="under_arm_so101_v1"/>
            <geom class="collision" size="0.07 0.01 0.03" pos="-0.05 0 0.0182" quat="0 1 0 0" type="box"/>
            <geom class="visual" pos="-0.06485 -0.032 0.018" quat="0 -1 0 0" material="motor_holder_so101_wrist_v1_material" mesh="motor_holder_so101_wrist_v1"/>
            <geom class="collision" size="0.023 0.013 0.018" pos="-0.125 0.005 0.018" quat="0 -1 0 0" type="box"/>
            <geom class="visual" pos="-0.1224 0.0052 0.0187" quat="0 0 1 0" material="sts3215_03a_v1_material" mesh="sts3215_03a_v1"/>
            <body name="wrist" pos="-0.1349 0.0052 0" quat="0.707107 0 0 -0.707107">
              <inertial pos="-0.000103312 -0.0386143 0.0281156" quat="0.967143 0.254226 0.00162226 -0.000146307" mass="0.079" diaginertia="3.68265e-05 2.74474e-05 1.89434e-05"/>
              <joint name="wrist_flex" class="sts3215" pos="0 0 0" axis="0 0 1" range="-1.65806 1.65806"/>
              <geom class="visual" pos="0 -0.0424 0.0306" quat="0.5 0.5 0.5 -0.5" material="sts3215_03a_no_horn_v1_material" mesh="sts3215_03a_no_horn_v1"/>
              <geom class="collision" size="0.029 0.015 0.018" pos="0 -0.0424 0.0256" quat="0.5 0.5 0.5 -0.5" type="box"/>
              <geom class="visual" pos="0 -0.028 0.0181" quat="0.5 -0.5 -0.5 -0.5" material="wrist_roll_pitch_so101_v2_material" mesh="wrist_roll_pitch_so101_v2"/>
              <geom class="collision" size="0.027 0.01 0.03" pos="0 -0.02 0.0191" quat="0.5 -0.5 -0.5 -0.5" type="box"/>
              <body name="gripper" pos="0 -0.0611 0.0181" quat="0.0172091 -0.0172091 0.706897 0.706897">
                <inertial pos="0.000214 0.000245 -0.025187" quat="0.600717 0.355993 0.35863 0.61951" mass="0.087" diaginertia="4.33735e-05 3.77229e-05 2.42839e-05"/>
                <joint name="wrist_roll" class="sts3215" pos="0 0 0" axis="0 0 1" range="-2.74385 2.74385"/>
                <geom class="visual" pos="0.0077 0.0001 -0.0234" quat="0.707107 -0.707107 0 0" material="sts3215_03a_v1_material" mesh="sts3215_03a_v1"/>
                <geom class="visual" pos="0 -0.000218 0.00095" quat="0 1 0 0" material="wrist_roll_follower_so101_v1_material" mesh="wrist_roll_follower_so101_v1"/>
                <geom class="collision" size="0.01 0.01 0.018" pos="0 -0.000218 0.00095" quat="0 1 0 0" type="box"/>
                <geom name="fixed_jaw_box1" class="collision_gripper" size="0.0325 0.015 0.015" pos="-0.0025 0 -0.022" type="box" mass="0"/>
                <geom name="fixed_jaw_box2" class="collision_gripper" size="0.01 0.015 0.005" pos="-0.024 0 -0.04" type="box" mass="0"/>
                <geom name="fixed_jaw_sph_tip1" class="collision_gripper" size="0.00075" pos="-0.0081 0 -0.101" mass="0"/>
                <geom name="fixed_jaw_sph_tip2" class="collision_gripper" size="0.00075" pos="-0.0081 0.0035 -0.0975" mass="0"/>
                <geom name="fixed_jaw_sph_tip3" class="collision_gripper" size="0.00075" pos="-0.0081 -0.0035 -0.0975" mass="0"/>
                <geom class="collision_gripper_mesh" pos="0 -0.000218 0.00095" quat="0 1 0 0" type="mesh" mass="0" mesh="wrist_roll_follower_so101_gripper_part0_v1"/>
                <geom name="fixed_jaw_box3" class="collision_gripper" size="0.0011 0.002" pos="-0.009 0 -0.103" quat="0.707388 0.706825 0 0" type="capsule" mass="0"/>
                <geom name="fixed_jaw_box4" class="collision_gripper" size="0.001 0.004 0.004" pos="-0.009 0 -0.0982" type="box" mass="0"/>
                <geom name="fixed_jaw_box5" class="collision_gripper" size="0.001 0.005 0.006" pos="-0.0108 0 -0.0905" type="box" mass="0"/>
                <geom name="fixed_jaw_box6" class="collision_gripper" size="0.001 0.009 0.008" pos="-0.0125 0 -0.0727" type="box" mass="0"/>
                <geom name="fixed_jaw_box7" class="collision_gripper" size="0.001 0.01 0.008" pos="-0.0143 0 -0.053" type="box" mass="0"/>
                <site name="gripperframe" pos="0.012 -0.000218 -0.098127" quat="0.707107 0 0.707107 0" group="3"/>
                <body name="camera_mount">
                  <geom class="visual" pos="0 0.065 -0.035" quat="0.62068 0.338758 0.620409 0.339252" material="arducam_material" mesh="ArduCam_M12Lens"/>
                  <geom class="visual" pos="0 -0.000218 0.00095" quat="0 1 0 0" mass="0.012" material="wrist_roll_follower_so101_v1_material" mesh="wrist_roll_follower_so101_camera_mount"/>
                  <geom name="camera_box1" class="collision_gripper" size="0.015 0.015 0.003" pos="-0.0025 0.03 -0.03" type="box" mass="0"/>
                  <geom name="camera_box2" class="collision_gripper" size="0.021 0.021 0.003" pos="-0.001 0.06 -0.04" quat="0.962425 -0.271547 0 0" type="box" mass="0"/>
                  <camera name="wrist_cam" pos="0 0.055 -0.045" quat="4.4458e-05 -1.30251e-05 0.281157 0.959662" resolution="1280 800" fovy="70"/>
                </body>
                <body name="moving_jaw_so101_v1" pos="0.0202 0.0188 -0.0234" quat="0.707107 0.707107 0 0">
                  <inertial pos="-0.001575 -0.0300244 0.0192755" quat="0.695265 0.717965 -0.0245618 -0.0230097" mass="0.012" diaginertia="6.63582e-06 5.29092e-06 1.86523e-06"/>
                  <joint name="gripper" class="sts3215" pos="0 0 0" axis="0 0 1" range="-0.174533 1.74533"/>
                  <geom class="visual" pos="0 0 0.0189" quat="1 0 0 0" material="moving_jaw_so101_v1_material" mesh="moving_jaw_so101_v1"/>
                  <geom class="collision_gripper_mesh" pos="0 0 0.0189" quat="1 0 0 0" type="mesh" mass="0" mesh="moving_jaw_so101_gripper_part0_v1"/>
                  <geom class="collision_gripper_mesh" pos="0 0 0.0189" quat="1 0 0 0" type="mesh" mass="0" mesh="moving_jaw_so101_gripper_part1_v1"/>
                  <geom name="moving_jaw_box1" class="collision_gripper" size="0.01 0.01 0.015" pos="0 -0.013 0.019" type="box" mass="0"/>
                  <geom name="moving_jaw_sph_tip1" class="collision_gripper" size="0.00075" pos="-0.012 -0.078 0.0192" mass="0"/>
                  <geom name="moving_jaw_sph_tip2" class="collision_gripper" size="0.00075" pos="-0.012 -0.0745 0.0225" mass="0"/>
                  <geom name="moving_jaw_sph_tip3" class="collision_gripper" size="0.00075" pos="-0.012 -0.0745 0.0155" mass="0"/>
                  <geom name="moving_jaw_box2" class="collision_gripper" size="0.001 0.004 0.004" pos="-0.0113 -0.076 0.01875" type="box" mass="0"/>
                  <geom name="moving_jaw_box3" class="collision_gripper" size="0.001 0.005 0.006" pos="-0.0093 -0.067 0.01875" type="box" mass="0"/>
                </body>
              </body>
            </body>
          </body>
        </body>
      </body>
    </body>
    <body name="d435i" childclass="d435i" pos="0.5 0.5 0.6" quat="0.353556 0.853554 -0.35355 -0.146446">
      <geom class="d435i_visual" mass="0" material="IR_Lens" mesh="d435i_0"/>
      <geom class="d435i_visual" mass="0" material="IR_Emitter_Lens" mesh="d435i_1"/>
      <geom class="visual" material="IR_Rim" mesh="d435i_2"/>
      <geom class="visual" material="IR_Lens" mesh="d435i_3"/>
      <geom class="visual" material="Cameras_Gray" mesh="d435i_4"/>
      <geom class="visual" material="Black_Acrylic" mesh="d435i_5"/>
      <geom class="visual" material="Black_Acrylic" mesh="d435i_6"/>
      <geom class="visual" material="RGB_Pupil" mesh="d435i_7"/>
      <geom class="visual" mass="0.072" material="Metal_Casing" mesh="d435i_8"/>
      <geom class="d435i_collision" size="0.0133327 0.0316323" pos="7.48124e-05 0.000188096 -0.0124624" quat="0.0290189 0.708312 0.0275476 0.704764" type="capsule" mass="0"/>
      <camera name="realsense_d435i" pos="0 0 0" quat="1.32679e-06 0 1 0" fovy="58"/>
    </body>
    <body name="box" pos="0.35 0 0.03">
      <joint type="free"/>
      <geom name="box_geom" size="0.0238254 0.022088 0.025449" type="box" contype="2" conaffinity="3" condim="4" friction="1 0.1 0.005" solref="0.008" solimp="0.99 0.999" rgba="0.0878863 0.1999 0.0980911 1"/>
    </body>
    <body name="box2" pos="0.284143 0.180958 0.03">
      <joint type="free"/>
      <geom name="box2_geom" size="0.0175741 0.0242323 0.0310118" type="box" contype="2" conaffinity="3" condim="4" friction="1 0.1 0.005" solref="0.008" solimp="0.99 0.999" rgba="0.0107209 0.0532334 0.621674 1"/>
    </body>
    <body name="air_camera_mount" pos="0.5 0.5 0.6" quat="0.353556 0.853554 -0.35355 -0.146446"/>
  </worldbody>

  <actuator>
    <general name="shoulder_pan" class="sts3215" joint="shoulder_pan" ctrlrange="-1.91986 1.91986"/>
    <general name="shoulder_lift" class="sts3215" joint="shoulder_lift" ctrlrange="-1.74533 1.74533"/>
    <general name="elbow_flex" class="sts3215" joint="elbow_flex" ctrlrange="-1.69 1.69"/>
    <general name="wrist_flex" class="sts3215" joint="wrist_flex" ctrlrange="-1.65806 1.65806"/>
    <general name="wrist_roll" class="sts3215" joint="wrist_roll" ctrlrange="-2.74385 2.84121"/>
    <general name="gripper" class="sts3215" joint="gripper" ctrlrange="-0.17453 1.74533"/>
  </actuator>
</mujoco>
